Workbook

Sheet Final
A1: Year | B1: Month | C1: Day | D1: Hour | E1: Weekday | F1: Total events
A2: 2025 | B2: 4 | C2: 30 | D2: 00-01 | E2: Wednesday | F2: 21
A3: 2025 | B3: 4 | C3: 30 | D3: 03-04 | E3: Wednesday | F3: 1
A4: 2025 | B4: 4 | C4: 30 | D4: 04-05 | E4: Wednesday | F4: 3
A5: 2025 | B5: 4 | C5: 30 | D5: 05-06 | E5: Wednesday | F5: 3
A6: 2025 | B6: 4 | C6: 30 | D6: 06-07 | E6: Wednesday | F6: 11
A7: 2025 | B7: 4 | C7: 30 | D7: 07-08 | E7: Wednesday | F7: 6
A8: 2025 | B8: 4 | C8: 30 | D8: 08-09 | E8: Wednesday | F8: 2
A9: 2025 | B9: 4 | C9: 30 | D9: 09-10 | E9: Wednesday | F9: 2
A10: 2025 | B10: 4 | C10: 30 | D10: 10-11 | E10: Wednesday | F10: 1
A11: 2025 | B11: 4 | C11: 30 | D11: 11-12 | E11: Wednesday | F11: 1
A12: 2025 | B12: 4 | C12: 30 | D12: 12-13 | E12: Wednesday | F12: 2
A13: 2025 | B13: 4 | C13: 30 | D13: 20-21 | E13: Wednesday | F13: 1
... A5353: 2025 | B5353: 12 | C5353: 9 | D5353: 11-12 | E5353: Tuesday | F5353: 11

Sheet Untitled Report_Insights_2025-0
A1: Start Timestamp | B1: Start Timestamp | C1: Start Timestamp | D1: Start Timestamp | E1: Hour | F1: Total Events of Charging Ended | I1: Year | J1: Month | K1: Day | L1: Hour | M1: Weekday | N1: Total events | Q1: Year | R1: Month | S1: Day | T1: Hour | U1: Weekday | V1: Total events
A2: 2025 | B2: 45748 | C2: Apr 30, 2025 | D2: Wednesday | E2: 00-01 | F2: 21 | I2: =A2 -> 2025 | J2: =INDEX(Sheet1!F:F,MATCH('Untitled Report_Insights_2025-0'!B2,Sheet1!E:E,0)) -> 4 | K2: =INDEX(Sheet1!B:B,MATCH('Untitled Report_Insights_2025-0'!C2,Sheet1!A:A,0)) -> 30 | L2: =INDEX(Sheet1!J:J,MATCH('Untitled Report_Insights_2025-0'!E2,Sheet1!I:I,0)) -> 00-01 | M2: =D2 -> Wednesday | N2: =F2 -> 21 | Q2: 2025 | R2: 4 | S2: 30 | T2: 00-01 | U2: Wednesday | V2: 21
A3: 2025 | B3: 45748 | C3: Apr 30, 2025 | D3: Wednesday | E3: 45750 | F3: 1 | I3: =A3 -> 2025 | J3: =INDEX(Sheet1!F:F,MATCH('Untitled Report_Insights_2025-0'!B3,Sheet1!E:E,0)) -> 4 | K3: =INDEX(Sheet1!B:B,MATCH('Untitled Report_Insights_2025-0'!C3,Sheet1!A:A,0)) -> 30 | L3: =INDEX(Sheet1!J:J,MATCH('Untitled Report_Insights_2025-0'!E3,Sheet1!I:I,0)) -> 03-04 | M3: =D3 -> Wednesday | N3: =F3 -> 1 | Q3: 2025 | R3: 4 | S3: 30 | T3: 03-04 | U3: Wednesday | V3: 1
A4: 2025 | B4: 45748 | C4: Apr 30, 2025 | D4: Wednesday | E4: 45781 | F4: 3 | I4: =A4 -> 2025 | J4: =INDEX(Sheet1!F:F,MATCH('Untitled Report_Insights_2025-0'!B4,Sheet1!E:E,0)) -> 4 | K4: =INDEX(Sheet1!B:B,MATCH('Untitled Report_Insights_2025-0'!C4,Sheet1!A:A,0)) -> 30 | L4: =INDEX(Sheet1!J:J,MATCH('Untitled Report_Insights_2025-0'!E4,Sheet1!I:I,0)) -> 04-05 | M4: =D4 -> Wednesday | N4: =F4 -> 3 | Q4: 2025 | R4: 4 | S4: 30 | T4: 04-05 | U4: Wednesday | V4: 3
A5: 2025 | B5: 45748 | C5: Apr 30, 2025 | D5: Wednesday | E5: 45813 | F5: 3 | I5: =A5 -> 2025 | J5: =INDEX(Sheet1!F:F,MATCH('Untitled Report_Insights_2025-0'!B5,Sheet1!E:E,0)) -> 4 | K5: =INDEX(Sheet1!B:B,MATCH('Untitled Report_Insights_2025-0'!C5,Sheet1!A:A,0)) -> 30 | L5: =INDEX(Sheet1!J:J,MATCH('Untitled Report_Insights_2025-0'!E5,Sheet1!I:I,0)) -> 05-06 | M5: =D5 -> Wednesday | N5: =F5 -> 3 | Q5: 2025 | R5: 4 | S5: 30 | T5: 05-06 | U5: Wednesday | V5: 3
A6: 2025 | B6: 45748 | C6: Apr 30, 2025 | D6: Wednesday | E6: 45844 | F6: 11 | I6: =A6 -> 2025 | J6: =INDEX(Sheet1!F:F,MATCH('Untitled Report_Insights_2025-0'!B6,Sheet1!E:E,0)) -> 4 | K6: =INDEX(Sheet1!B:B,MATCH('Untitled Report_Insights_2025-0'!C6,Sheet1!A:A,0)) -> 30 | L6: =INDEX(Sheet1!J:J,MATCH('Untitled Report_Insights_2025-0'!E6,Sheet1!I:I,0)) -> 06-07 | M6: =D6 -> Wednesday | N6: =F6 -> 11 | Q6: 2025 | R6: 4 | S6: 30 | T6: 06-07 | U6: Wednesday | V6: 11
A7: 2025 | B7: 45748 | C7: Apr 30, 2025 | D7: Wednesday | E7: 45876 | F7: 6 | I7: =A7 -> 2025 | J7: =INDEX(Sheet1!F:F,MATCH('Untitled Report_Insights_2025-0'!B7,Sheet1!E:E,0)) -> 4 | K7: =INDEX(Sheet1!B:B,MATCH('Untitled Report_Insights_2025-0'!C7,Sheet1!A:A,0)) -> 30 | L7: =INDEX(Sheet1!J:J,MATCH('Untitled Report_Insights_2025-0'!E7,Sheet1!I:I,0)) -> 07-08 | M7: =D7 -> Wednesday | N7: =F7 -> 6 | Q7: 2025 | R7: 4 | S7: 30 | T7: 07-08 | U7: Wednesday | V7: 6
A8: 2025 | B8: 45748 | C8: Apr 30, 2025 | D8: Wednesday | E8: 45908 | F8: 2 | I8: =A8 -> 2025 | J8: =INDEX(Sheet1!F:F,MATCH('Untitled Report_Insights_2025-0'!B8,Sheet1!E:E,0)) -> 4 | K8: =INDEX(Sheet1!B:B,MATCH('Untitled Report_Insights_2025-0'!C8,Sheet1!A:A,0)) -> 30 | L8: =INDEX(Sheet1!J:J,MATCH('Untitled Report_Insights_2025-0'!E8,Sheet1!I:I,0)) -> 08-09 | M8: =D8 -> Wednesday | N8: =F8 -> 2 | Q8: 2025 | R8: 4 | S8: 30 | T8: 08-09 | U8: Wednesday | V8: 2
A9: 2025 | B9: 45748 | C9: Apr 30, 2025 | D9: Wednesday | E9: 45939 | F9: 2 | I9: =A9 -> 2025 | J9: =INDEX(Sheet1!F:F,MATCH('Untitled Report_Insights_2025-0'!B9,Sheet1!E:E,0)) -> 4 | K9: =INDEX(Sheet1!B:B,MATCH('Untitled Report_Insights_2025-0'!C9,Sheet1!A:A,0)) -> 30 | L9: =INDEX(Sheet1!J:J,MATCH('Untitled Report_Insights_2025-0'!E9,Sheet1!I:I,0)) -> 09-10 | M9: =D9 -> Wednesday | N9: =F9 -> 2 | Q9: 2025 | R9: 4 | S9: 30 | T9: 09-10 | U9: Wednesday | V9: 2
A10: 2025 | B10: 45748 | C10: Apr 30, 2025 | D10: Wednesday | E10: 45971 | F10: 1 | I10: =A10 -> 2025 | J10: =INDEX(Sheet1!F:F,MATCH('Untitled Report_Insights_2025-0'!B10,Sheet1!E:E,0)) -> 4 | K10: =INDEX(Sheet1!B:B,MATCH('Untitled Report_Insights_2025-0'!C10,Sheet1!A:A,0)) -> 30 | L10: =INDEX(Sheet1!J:J,MATCH('Untitled Report_Insights_2025-0'!E10,Sheet1!I:I,0)) -> 10-11 | M10: =D10 -> Wednesday | N10: =F10 -> 1 | Q10: 2025 | R10: 4 | S10: 30 | T10: 10-11 | U10: Wednesday | V10: 1
A11: 2025 | B11: 45748 | C11: Apr 30, 2025 | D11: Wednesday | E11: 46002 | F11: 1 | I11: =A11 -> 2025 | J11: =INDEX(Sheet1!F:F,MATCH('Untitled Report_Insights_2025-0'!B11,Sheet1!E:E,0)) -> 4 | K11: =INDEX(Sheet1!B:B,MATCH('Untitled Report_Insights_2025-0'!C11,Sheet1!A:A,0)) -> 30 | L11: =INDEX(Sheet1!J:J,MATCH('Untitled Report_Insights_2025-0'!E11,Sheet1!I:I,0)) -> 11-12 | M11: =D11 -> Wednesday | N11: =F11 -> 1 | Q11: 2025 | R11: 4 | S11: 30 | T11: 11-12 | U11: Wednesday | V11: 1
A12: 2025 | B12: 45748 | C12: Apr 30, 2025 | D12: Wednesday | E12: 41609 | F12: 2 | I12: =A12 -> 2025 | J12: =INDEX(Sheet1!F:F,MATCH('Untitled Report_Insights_2025-0'!B12,Sheet1!E:E,0)) -> 4 | K12: =INDEX(Sheet1!B:B,MATCH('Untitled Report_Insights_2025-0'!C12,Sheet1!A:A,0)) -> 30 | L12: =INDEX(Sheet1!J:J,MATCH('Untitled Report_Insights_2025-0'!E12,Sheet1!I:I,0)) -> 12-13 | M12: =D12 -> Wednesday | N12: =F12 -> 2 | Q12: 2025 | R12: 4 | S12: 30 | T12: 12-13 | U12: Wednesday | V12: 2
A13: 2025 | B13: 45748 | C13: Apr 30, 2025 | D13: Wednesday | E13: 20-21 | F13: 1 | I13: =A13 -> 2025 | J13: =INDEX(Sheet1!F:F,MATCH('Untitled Report_Insights_2025-0'!B13,Sheet1!E:E,0)) -> 4 | K13: =INDEX(Sheet1!B:B,MATCH('Untitled Report_Insights_2025-0'!C13,Sheet1!A:A,0)) -> 30 | L13: =INDEX(Sheet1!J:J,MATCH('Untitled Report_Insights_2025-0'!E13,Sheet1!I:I,0)) -> 20-21 | M13: =D13 -> Wednesday | N13: =F13 -> 1 | Q13: 2025 | R13: 4 | S13: 30 | T13: 20-21 | U13: Wednesday | V13: 1
A14: 2025 | B14: 45870 | C14: Aug 1, 2025 | D14: Friday | E14: 00-01 | F14: 90 | I14: =A14 -> 2025 | J14: =INDEX(Sheet1!F:F,MATCH('Untitled Report_Insights_2025-0'!B14,Sheet1!E:E,0)) -> 8 | K14: =INDEX(Sheet1!B:B,MATCH('Untitled Report_Insights_2025-0'!C14,Sheet1!A:A,0)) -> 1 | L14: =INDEX(Sheet1!J:J,MATCH('Untitled Report_Insights_2025-0'!E14,Sheet1!I:I,0)) -> 00-01 | M14: =D14 -> Friday | N14: =F14 -> 90 | Q14: 2025 | R14: 5 | S14: 1 | T14: 00-01 | U14: Thursday | V14: 41
A15: 2025 | B15: 45870 | C15: Aug 1, 2025 | D15: Friday | E15: 45689 | F15: 30 | I15: =A15 -> 2025 | J15: =INDEX(Sheet1!F:F,MATCH('Untitled Report_Insights_2025-0'!B15,Sheet1!E:E,0)) -> 8 | K15: =INDEX(Sheet1!B:B,MATCH('Untitled Report_Insights_2025-0'!C15,Sheet1!A:A,0)) -> 1 | L15: =INDEX(Sheet1!J:J,MATCH('Untitled Report_Insights_2025-0'!E15,Sheet1!I:I,0)) -> 01-02 | M15: =D15 -> Friday | N15: =F15 -> 30 | Q15: 2025 | R15: 5 | S15: 1 | T15: 01-02 | U15: Thursday | V15: 16
A16: 2025 | B16: 45870 | C16: Aug 1, 2025 | D16: Friday | E16: 45718 | F16: 20 | I16: =A16 -> 2025 | J16: =INDEX(Sheet1!F:F,MATCH('Untitled Report_Insights_2025-0'!B16,Sheet1!E:E,0)) -> 8 | K16: =INDEX(Sheet1!B:B,MATCH('Untitled Report_Insights_2025-0'!C16,Sheet1!A:A,0)) -> 1 | L16: =INDEX(Sheet1!J:J,MATCH('Untitled Report_Insights_2025-0'!E16,Sheet1!I:I,0)) -> 02-03 | M16: =D16 -> Friday | N16: =F16 -> 20 | Q16: 2025 | R16: 5 | S16: 1 | T16: 02-03 | U16: Thursday | V16: 18
A17: 2025 | B17: 45870 | C17: Aug 1, 2025 | D17: Friday | E17: 45750 | F17: 27 | I17: =A17 -> 2025 | J17: =INDEX(Sheet1!F:F,MATCH('Untitled Report_Insights_2025-0'!B17,Sheet1!E:E,0)) -> 8 | K17: =INDEX(Sheet1!B:B,MATCH('Untitled Report_Insights_2025-0'!C17,Sheet1!A:A,0)) -> 1 | L17: =INDEX(Sheet1!J:J,MATCH('Untitled Report_Insights_2025-0'!E17,Sheet1!I:I,0)) -> 03-04 | M17: =D17 -> Friday | N17: =F17 -> 27 | Q17: 2025 | R17: 5 | S17: 1 | T17: 03-04 | U17: Thursday | V17: 11
A18: 2025 | B18: 45870 | C18: Aug 1, 2025 | D18: Friday | E18: 45781 | F18: 19 | I18: =A18 -> 2025 | J18: =INDEX(Sheet1!F:F,MATCH('Untitled Report_Insights_2025-0'!B18,Sheet1!E:E,0)) -> 8 | K18: =INDEX(Sheet1!B:B,MATCH('Untitled Report_Insights_2025-0'!C18,Sheet1!A:A,0)) -> 1 | L18: =INDEX(Sheet1!J:J,MATCH('Untitled Report_Insights_2025-0'!E18,Sheet1!I:I,0)) -> 04-05 | M18: =D18 -> Friday | N18: =F18 -> 19 | Q18: 2025 | R18: 5 | S18: 1 | T18: 04-05 | U18: Thursday | V18: 13
A19: 2025 | B19: 45870 | C19: Aug 1, 2025 | D19: Friday | E19: 45813 | F19: 25 | I19: =A19 -> 2025 | J19: =INDEX(Sheet1!F:F,MATCH('Untitled Report_Insights_2025-0'!B19,Sheet1!E:E,0)) -> 8 | K19: =INDEX(Sheet1!B:B,MATCH('Untitled Report_Insights_2025-0'!C19,Sheet1!A:A,0)) -> 1 | L19: =INDEX(Sheet1!J:J,MATCH('Untitled Report_Insights_2025-0'!E19,Sheet1!I:I,0)) -> 05-06 | M19: =D19 -> Friday | N19: =F19 -> 25 | Q19: 2025 | R19: 5 | S19: 1 | T19: 05-06 | U19: Thursday | V19: 13
A20: 2025 | B20: 45870 | C20: Aug 1, 2025 | D20: Friday | E20: 45844 | F20: 29 | I20: =A20 -> 2025 | J20: =INDEX(Sheet1!F:F,MATCH('Untitled Report_Insights_2025-0'!B20,Sheet1!E:E,0)) -> 8 | K20: =INDEX(Sheet1!B:B,MATCH('Untitled Report_Insights_2025-0'!C20,Sheet1!A:A,0)) -> 1 | L20: =INDEX(Sheet1!J:J,MATCH('Untitled Report_Insights_2025-0'!E20,Sheet1!I:I,0)) -> 06-07 | M20: =D20 -> Friday | N20: =F20 -> 29 | Q20: 2025 | R20: 5 | S20: 1 | T20: 06-07 | U20: Thursday | V20: 38
A21: 2025 | B21: 45870 | C21: Aug 1, 2025 | D21: Friday | E21: 45876 | F21: 100 | I21: =A21 -> 2025 | J21: =INDEX(Sheet1!F:F,MATCH('Untitled Report_Insights_2025-0'!B21,Sheet1!E:E,0)) -> 8 | K21: =INDEX(Sheet1!B:B,MATCH('Untitled Report_Insights_2025-0'!C21,Sheet1!A:A,0)) -> 1 | L21: =INDEX(Sheet1!J:J,MATCH('Untitled Report_Insights_2025-0'!E21,Sheet1!I:I,0)) -> 07-08 | M21: =D21 -> Friday | N21: =F21 -> 100 | Q21: 2025 | R21: 5 | S21: 1 | T21: 07-08 | U21: Thursday | V21: 54
A22: 2025 | B22: 45870 | C22: Aug 1, 2025 | D22: Friday | E22: 45908 | F22: 132 | I22: =A22 -> 2025 | J22: =INDEX(Sheet1!F:F,MATCH('Untitled Report_Insights_2025-0'!B22,Sheet1!E:E,0)) -> 8 | K22: =INDEX(Sheet1!B:B,MATCH('Untitled Report_Insights_2025-0'!C22,Sheet1!A:A,0)) -> 1 | L22: =INDEX(Sheet1!J:J,MATCH('Untitled Report_Insights_2025-0'!E22,Sheet1!I:I,0)) -> 08-09 | M22: =D22 -> Friday | N22: =F22 -> 132 | Q22: 2025 | R22: 5 | S22: 1 | T22: 08-09 | U22: Thursday | V22: 100
A23: 2025 | B23: 45870 | C23: Aug 1, 2025 | D23: Friday | E23: 45939 | F23: 256 | I23: =A23 -> 2025 | J23: =INDEX(Sheet1!F:F,MATCH('Untitled Report_Insights_2025-0'!B23,Sheet1!E:E,0)) -> 8 | K23: =INDEX(Sheet1!B:B,MATCH('Untitled Report_Insights_2025-0'!C23,Sheet1!A:A,0)) -> 1 | L23: =INDEX(Sheet1!J:J,MATCH('Untitled Report_Insights_2025-0'!E23,Sheet1!I:I,0)) -> 09-10 | M23: =D23 -> Friday | N23: =F23 -> 256 | Q23: 2025 | R23: 5 | S23: 1 | T23: 09-10 | U23: Thursday | V23: 139
A24: 2025 | B24: 45870 | C24: Aug 1, 2025 | D24: Friday | E24: 45971 | F24: 378 | I24: =A24 -> 2025 | J24: =INDEX(Sheet1!F:F,MATCH('Untitled Report_Insights_2025-0'!B24,Sheet1!E:E,0)) -> 8 | K24: =INDEX(Sheet1!B:B,MATCH('Untitled Report_Insights_2025-0'!C24,Sheet1!A:A,0)) -> 1 | L24: =INDEX(Sheet1!J:J,MATCH('Untitled Report_Insights_2025-0'!E24,Sheet1!I:I,0)) -> 10-11 | M24: =D24 -> Friday | N24: =F24 -> 378 | Q24: 2025 | R24: 5 | S24: 1 | T24: 10-11 | U24: Thursday | V24: 211
A25: 2025 | B25: 45870 | C25: Aug 1, 2025 | D25: Friday | E25: 46002 | F25: 522 | I25: =A25 -> 2025 | J25: =INDEX(Sheet1!F:F,MATCH('Untitled Report_Insights_2025-0'!B25,Sheet1!E:E,0)) -> 8 | K25: =INDEX(Sheet1!B:B,MATCH('Untitled Report_Insights_2025-0'!C25,Sheet1!A:A,0)) -> 1 | L25: =INDEX(Sheet1!J:J,MATCH('Untitled Report_Insights_2025-0'!E25,Sheet1!I:I,0)) -> 11-12 | M25: =D25 -> Friday | N25: =F25 -> 522 | Q25: 2025 | R25: 5 | S25: 1 | T25: 11-12 | U25: Thursday | V25: 270
A26: 2025 | B26: 45870 | C26: Aug 1, 2025 | D26: Friday | E26: 41609 | F26: 614 | I26: =A26 -> 2025 | J26: =INDEX(Sheet1!F:F,MATCH('Untitled Report_Insights_2025-0'!B26,Sheet1!E:E,0)) -> 8 | K26: =INDEX(Sheet1!B:B,MATCH('Untitled Report_Insights_2025-0'!C26,Sheet1!A:A,0)) -> 1 | L26: =INDEX(Sheet1!J:J,MATCH('Untitled Report_Insights_2025-0'!E26,Sheet1!I:I,0)) -> 12-13 | M26: =D26 -> Friday | N26: =F26 -> 614 | Q26: 2025 | R26: 5 | S26: 1 | T26: 12-13 | U26: Thursday | V26: 342
A27: 2025 | B27: 45870 | C27: Aug 1, 2025 | D27: Friday | E27: 13-14 | F27: 644 | I27: =A27 -> 2025 | J27: =INDEX(Sheet1!F:F,MATCH('Untitled Report_Insights_2025-0'!B27,Sheet1!E:E,0)) -> 8 | K27: =INDEX(Sheet1!B:B,MATCH('Untitled Report_Insights_2025-0'!C27,Sheet1!A:A,0)) -> 1 | L27: =INDEX(Sheet1!J:J,MATCH('Untitled Report_Insights_2025-0'!E27,Sheet1!I:I,0)) -> 13-14 | M27: =D27 -> Friday | N27: =F27 -> 644 | Q27: 2025 | R27: 5 | S27: 1 | T27: 13-14 | U27: Thursday | V27: 340
A28: 2025 | B28: 45870 | C28: Aug 1, 2025 | D28: Friday | E28: 14-15 | F28: 635 | I28: =A28 -> 2025 | J28: =INDEX(Sheet1!F:F,MATCH('Untitled Report_Insights_2025-0'!B28,Sheet1!E:E,0)) -> 8 | K28: =INDEX(Sheet1!B:B,MATCH('Untitled Report_Insights_2025-0'!C28,Sheet1!A:A,0)) -> 1 | L28: =INDEX(Sheet1!J:J,MATCH('Untitled Report_Insights_2025-0'!E28,Sheet1!I:I,0)) -> 14-15 | M28: =D28 -> Friday | N28: =F28 -> 635 | Q28: 2025 | R28: 5 | S28: 1 | T28: 14-15 | U28: Thursday | V28: 363
A29: 2025 | B29: 45870 | C29: Aug 1, 2025 | D29: Friday | E29: 15-16 | F29: 633 | I29: =A29 -> 2025 | J29: =INDEX(Sheet1!F:F,MATCH('Untitled Report_Insights_2025-0'!B29,Sheet1!E:E,0)) -> 8 | K29: =INDEX(Sheet1!B:B,MATCH('Untitled Report_Insights_2025-0'!C29,Sheet1!A:A,0)) -> 1 | L29: =INDEX(Sheet1!J:J,MATCH('Untitled Report_Insights_2025-0'!E29,Sheet1!I:I,0)) -> 15-16 | M29: =D29 -> Friday | N29: =F29 -> 633 | Q29: 2025 | R29: 5 | S29: 1 | T29: 15-16 | U29: Thursday | V29: 350
A30: 2025 | B30: 45870 | C30: Aug 1, 2025 | D30: Friday | E30: 16-17 | F30: 643 | I30: =A30 -> 2025 | J30: =INDEX(Sheet1!F:F,MATCH('Untitled Report_Insights_2025-0'!B30,Sheet1!E:E,0)) -> 8 | K30: =INDEX(Sheet1!B:B,MATCH('Untitled Report_Insights_2025-0'!C30,Sheet1!A:A,0)) -> 1 | L30: =INDEX(Sheet1!J:J,MATCH('Untitled Report_Insights_2025-0'!E30,Sheet1!I:I,0)) -> 16-17 | M30: =D30 -> Friday | N30: =F30 -> 643 | Q30: 2025 | R30: 5 | S30: 1 | T30: 16-17 | U30: Thursday | V30: 319
A31: 2025 | B31: 45870 | C31: Aug 1, 2025 | D31: Friday | E31: 17-18 | F31: 592 | I31: =A31 -> 2025 | J31: =INDEX(Sheet1!F:F,MATCH('Untitled Report_Insights_2025-0'!B31,Sheet1!E:E,0)) -> 8 | K31: =INDEX(Sheet1!B:B,MATCH('Untitled Report_Insights_2025-0'!C31,Sheet1!A:A,0)) -> 1 | L31: =INDEX(Sheet1!J:J,MATCH('Untitled Report_Insights_2025-0'!E31,Sheet1!I:I,0)) -> 17-18 | M31: =D31 -> Friday | N31: =F31 -> 592 | Q31: 2025 | R31: 5 | S31: 1 | T31: 17-18 | U31: Thursday | V31: 257
A32: 2025 | B32: 45870 | C32: Aug 1, 2025 | D32: Friday | E32: 18-19 | F32: 493 | I32: =A32 -> 2025 | J32: =INDEX(Sheet1!F:F,MATCH('Untitled Report_Insights_2025-0'!B32,Sheet1!E:E,0)) -> 8 | K32: =INDEX(Sheet1!B:B,MATCH('Untitled Report_Insights_2025-0'!C32,Sheet1!A:A,0)) -> 1 | L32: =INDEX(Sheet1!J:J,MATCH('Untitled Report_Insights_2025-0'!E32,Sheet1!I:I,0)) -> 18-19 | M32: =D32 -> Friday | N32: =F32 -> 493 | Q32: 2025 | R32: 5 | S32: 1 | T32: 18-19 | U32: Thursday | V32: 191
A33: 2025 | B33: 45870 | C33: Aug 1, 2025 | D33: Friday | E33: 19-20 | F33: 396 | I33: =A33 -> 2025 | J33: =INDEX(Sheet1!F:F,MATCH('Untitled Report_Insights_2025-0'!B33,Sheet1!E:E,0)) -> 8 | K33: =INDEX(Sheet1!B:B,MATCH('Untitled Report_Insights_2025-0'!C33,Sheet1!A:A,0)) -> 1 | L33: =INDEX(Sheet1!J:J,MATCH('Untitled Report_Insights_2025-0'!E33,Sheet1!I:I,0)) -> 19-20 | M33: =D33 -> Friday | N33: =F33 -> 396 | Q33: 2025 | R33: 5 | S33: 1 | T33: 19-20 | U33: Thursday | V33: 189
A34: 2025 | B34: 45870 | C34: Aug 1, 2025 | D34: Friday | E34: 20-21 | F34: 325 | I34: =A34 -> 2025 | J34: =INDEX(Sheet1!F:F,MATCH('Untitled Report_Insights_2025-0'!B34,Sheet1!E:E,0)) -> 8 | K34: =INDEX(Sheet1!B:B,MATCH('Untitled Report_Insights_2025-0'!C34,Sheet1!A:A,0)) -> 1 | L34: =INDEX(Sheet1!J:J,MATCH('Untitled Report_Insights_2025-0'!E34,Sheet1!I:I,0)) -> 20-21 | M34: =D34 -> Friday | N34: =F34 -> 325 | Q34: 2025 | R34: 5 | S34: 1 | T34: 20-21 | U34: Thursday | V34: 168
A35: 2025 | B35: 45870 | C35: Aug 1, 2025 | D35: Friday | E35: 21-22 | F35: 275 | I35: =A35 -> 2025 | J35: =INDEX(Sheet1!F:F,MATCH('Untitled Report_Insights_2025-0'!B35,Sheet1!E:E,0)) -> 8 | K35: =INDEX(Sheet1!B:B,MATCH('Untitled Report_Insights_2025-0'!C35,Sheet1!A:A,0)) -> 1 | L35: =INDEX(Sheet1!J:J,MATCH('Untitled Report_Insights_2025-0'!E35,Sheet1!I:I,0)) -> 21-22 | M35: =D35 -> Friday | N35: =F35 -> 275 | Q35: 2025 | R35: 5 | S35: 1 | T35: 21-22 | U35: Thursday | V35: 116
A36: 2025 | B36: 45870 | C36: Aug 1, 2025 | D36: Friday | E36: 22-23 | F36: 168 | I36: =A36 -> 2025 | J36: =INDEX(Sheet1!F:F,MATCH('Untitled Report_Insights_2025-0'!B36,Sheet1!E:E,0)) -> 8 | K36: =INDEX(Sheet1!B:B,MATCH('Untitled Report_Insights_2025-0'!C36,Sheet1!A:A,0)) -> 1 | L36: =INDEX(Sheet1!J:J,MATCH('Untitled Report_Insights_2025-0'!E36,Sheet1!I:I,0)) -> 22-23 | M36: =D36 -> Friday | N36: =F36 -> 168 | Q36: 2025 | R36: 5 | S36: 1 | T36: 22-23 | U36: Thursday | V36: 93
A37: 2025 | B37: 45870 | C37: Aug 1, 2025 | D37: Friday | E37: 23-00 | F37: 110 | I37: =A37 -> 2025 | J37: =INDEX(Sheet1!F:F,MATCH('Untitled Report_Insights_2025-0'!B37,Sheet1!E:E,0)) -> 8 | K37: =INDEX(Sheet1!B:B,MATCH('Untitled Report_Insights_2025-0'!C37,Sheet1!A:A,0)) -> 1 | L37: =INDEX(Sheet1!J:J,MATCH('Untitled Report_Insights_2025-0'!E37,Sheet1!I:I,0)) -> 23-00 | M37: =D37 -> Friday | N37: =F37 -> 110 | Q37: 2025 | R37: 5 | S37: 1 | T37: 23-00 | U37: Thursday | V37: 51
A38: 2025 | B38: 45870 | C38: Aug 10, 2025 | D38: Sunday | E38: 00-01 | F38: 81 | I38: =A38 -> 2025 | J38: =INDEX(Sheet1!F:F,MATCH('Untitled Report_Insights_2025-0'!B38,Sheet1!E:E,0)) -> 8 | K38: =INDEX(Sheet1!B:B,MATCH('Untitled Report_Insights_2025-0'!C38,Sheet1!A:A,0)) -> 10 | L38: =INDEX(Sheet1!J:J,MATCH('Untitled Report_Insights_2025-0'!E38,Sheet1!I:I,0)) -> 00-01 | M38: =D38 -> Sunday | N38: =F38 -> 81 | Q38: 2025 | R38: 5 | S38: 2 | T38: 00-01 | U38: Friday | V38: 43
A39: 2025 | B39: 45870 | C39: Aug 10, 2025 | D39: Sunday | E39: 45689 | F39: 47 | I39: =A39 -> 2025 | J39: =INDEX(Sheet1!F:F,MATCH('Untitled Report_Insights_2025-0'!B39,Sheet1!E:E,0)) -> 8 | K39: =INDEX(Sheet1!B:B,MATCH('Untitled Report_Insights_2025-0'!C39,Sheet1!A:A,0)) -> 10 | L39: =INDEX(Sheet1!J:J,MATCH('Untitled Report_Insights_2025-0'!E39,Sheet1!I:I,0)) -> 01-02 | M39: =D39 -> Sunday | N39: =F39 -> 47 | Q39: 2025 | R39: 5 | S39: 2 | T39: 01-02 | U39: Friday | V39: 17
A40: 2025 | B40: 45870 | C40: Aug 10, 2025 | D40: Sunday | E40: 45718 | F40: 39 | I40: =A40 -> 2025 | J40: =INDEX(Sheet1!F:F,MATCH('Untitled Report_Insights_2025-0'!B40,Sheet1!E:E,0)) -> 8 | K40: =INDEX(Sheet1!B:B,MATCH('Untitled Report_Insights_2025-0'!C40,Sheet1!A:A,0)) -> 10 | L40: =INDEX(Sheet1!J:J,MATCH('Untitled Report_Insights_2025-0'!E40,Sheet1!I:I,0)) -> 02-03 | M40: =D40 -> Sunday | N40: =F40 -> 39 | Q40: 2025 | R40: 5 | S40: 2 | T40: 02-03 | U40: Friday | V40: 10
...

Sheet Sheet1
A1: Apr 30, 2025 | B1: 30 | E1: 45748 | F1: 4 | I1: Hour
A2: Aug 1, 2025 | B2: 1 | E2: 45870 | F2: 8 | I2: 00-01 | J2: 00-01
A3: Aug 10, 2025 | B3: 10 | E3: 45992 | F3: 12 | I3: 45750 | J3: 03-04
A4: Aug 11, 2025 | B4: 11 | E4: 45839 | F4: 7 | I4: 45781 | J4: 04-05
A5: Aug 12, 2025 | B5: 12 | E5: 45809 | F5: 6 | I5: 45813 | J5: 05-06
A6: Aug 13, 2025 | B6: 13 | E6: 45778 | F6: 5 | I6: 45844 | J6: 06-07
A7: Aug 14, 2025 | B7: 14 | E7: 45962 | F7: 11 | I7: 45876 | J7: 07-08
A8: Aug 15, 2025 | B8: 15 | E8: 45931 | F8: 10 | I8: 45908 | J8: 08-09
A9: Aug 16, 2025 | B9: 16 | E9: 45901 | F9: 9 | I9: 45939 | J9: 09-10
A10: Aug 17, 2025 | B10: 17 | I10: 45971 | J10: 10-11
A11: Aug 18, 2025 | B11: 18 | I11: 46002 | J11: 11-12
A12: Aug 19, 2025 | B12: 19 | I12: 41609 | J12: 12-13
A13: Aug 2, 2025 | B13: 2 | I13: 20-21 | J13: 20-21
A14: Aug 20, 2025 | B14: 20 | I14: 45689 | J14: 01-02
A15: Aug 21, 2025 | B15: 21 | I15: 45718 | J15: 02-03
A16: Aug 22, 2025 | B16: 22 | I16: 13-14 | J16: 13-14
A17: Aug 23, 2025 | B17: 23 | I17: 14-15 | J17: 14-15
A18: Aug 24, 2025 | B18: 24 | I18: 15-16 | J18: 15-16
A19: Aug 25, 2025 | B19: 25 | I19: 16-17 | J19: 16-17
A20: Aug 26, 2025 | B20: 26 | I20: 17-18 | J20: 17-18
A21: Aug 27, 2025 | B21: 27 | I21: 18-19 | J21: 18-19
A22: Aug 28, 2025 | B22: 28 | I22: 19-20 | J22: 19-20
A23: Aug 29, 2025 | B23: 29 | I23: 21-22 | J23: 21-22
A24: Aug 3, 2025 | B24: 3 | I24: 22-23 | J24: 22-23
A25: Aug 30, 2025 | B25: 30 | I25: 23-00 | J25: 23-00
A26: Aug 31, 2025 | B26: 31
A27: Aug 4, 2025 | B27: 4
A28: Aug 5, 2025 | B28: 5
A29: Aug 6, 2025 | B29: 6
A30: Aug 7, 2025 | B30: 7
A31: Aug 8, 2025 | B31: 8
A32: Aug 9, 2025 | B32: 9
A33: Dec 1, 2025 | B33: 1
A34: Dec 2, 2025 | B34: 2
A35: Dec 3, 2025 | B35: 3
A36: Dec 4, 2025 | B36: 4
A37: Dec 5, 2025 | B37: 5
... A224: Sep 9, 2025 | B224: 9
